Workbook

Sheet 销售成本
A1: 产品销售成本计算表
A2: 编制单位：揭阳市揭东区磐东洪运来机械厂 2025年12月 单位:元
A3: 品名 项目 | B3: 期初库存 | D3: 本期销售 | F3: 本期生产 | H3: 本月销售成本 | K3: 期末库存
B4: 数量 | C4: 金额 | D4: 数量 | E4: 金额 | F4: 数量 | G4: 金额 | H4: 数量 | I4: 单价 | J4: 金额 | K4: 数量 | L4: 金额 | N4: 销售单价 | R4: 报关 | S4: 数量 | T4: 金额 | U4: 订单 | V4: 成本
A5: 铁制导轨（千克 | B5: 80175.77 | C5: 575550.95 | D5: 80175.77 | E5: 617291.35 | F5: =S5 | G5: =E5/D5*D5*测算表!$G$25*0+V5 | H5: =D5 | I5: =(C5+G5)/(B5+F5) | J5: =H5*I5 | K5: =B5+F5-H5 | L5: =C5+G5-J5 | N5: =E6/D6 | R5: 铁制导轨（千克 | S5: 58351.29 | T5: 421616.79 | U5: -76-77 | V5: =T5*测算表!$G$25
A6: 导轨（套 | D6: 966 | E6: 5463.72 | F6: =D6-B6 | G6: =E6/D6*F6*测算表!$G$25 | H6: =D6 | I6: =(C6+G6)/(B6+F6) | J6: =H6*I6 | K6: =B6+F6-H6 | L6: =C6+G6-J6 | N6: =E7/D7
A7: 滑轨（付 | D7: 37360 | E7: 140194.16 | F7: =D7-B7 | G7: =E7/D7*F7*测算表!$G$25 | H7: =D7 | I7: =(C7+G7)/(B7+F7) | J7: =H7*I7 | K7: =B7+F7-H7 | L7: =C7+G7-J7 | N7: =E10/D10
A8: 滑轨（套 | D8: 16590 | E8: 79355.75 | F8: =D8-B8 | G8: =E8/D8*F8*测算表!$G$25 | H8: =D8 | I8: =(C8+G8)/(B8+F8) | J8: =H8*I8 | K8: =B8+F8-H8 | L8: =C8+G8-J8
S9: =SUM(S5:S8) | T9: =SUM(T5:T8) | U9: =T9/S9 | V9: =SUM(V5:V8)
A12: 合 计 | B12: =SUM(B5:B11) | C12: =SUM(C5:C11) | D12: =SUM(D5:D11) | E12: =SUM(E5:E11) | F12: =SUM(F5:F11) | G12: =SUM(G5:G11) | H12: =SUM(H5:H11) | J12: =SUM(J5:J11) | K12: =SUM(K5:K11) | L12: =SUM(L5:L11)
J14: =H10*I10
E17: =E6+E7

Sheet 产品成本
A1: 产 品 成 本 核 算 表
A2: 编制单位:揭阳市揭东区磐东洪运来机械厂 2025.12 单位:元
A3: 项目 品名 | B3: 总计金额 | C3: =销售成本!A5 | D3: =销售成本!A6 | E3: =销售成本!A7 | F3: =销售成本!A8 | L3: =生产成本月结表!J4 | M3: =生产成本月结表!E4-测算表!K7
A4: 一、直接计入 | B4: =B5+B7 | C4: =C5+C7 | D4: =D5+D7 | E4: =E5+E7 | F4: =F5+F7 | K4: =SUM(C4:I4)-B4 | L4: =生产成本月结表!J5
A5: 1.原材料 | B5: =B16-B8-B7 | C5: =B5/B16*C16 | D5: =C5/C16*D16 | E5: =D5/D16*E16 | F5: =E5/E16*F16 | K5: =SUM(C5:I5)-B5 | L5: =生产成本月结表!E6 | M5: 动力余额
A6: 2.包装物
A7: 3.工资及福利 | B7: =B16*0.10743 | C7: =B7/B16*C16 | D7: =C7/C16*D16 | E7: =D7/D16*E16 | F7: =E7/E16*F16 | K7: =SUM(C7:I7)-B7
A8: 二、分配计入 | B8: =B9+B10+B11+B13 | C8: =C9+C10+C11+C13 | D8: =D9+D10+D11+D13 | E8: =E9+E10+E11+E13 | F8: =F9+F10+F11+F13 | K8: =SUM(C8:I8)-B8 | O8: 加工费余额
A9: 1.水电费 | B9: =B16/54*电费!D64 | C9: =B9/B16*C16 | D9: =C9/C16*D16 | E9: =D9/D16*E16 | F9: =E9/E16*F16 | K9: =SUM(C9:I9)-B9 | O9: =-165188.19+0-B11
A10: 2.折旧费 | B10: =测算表!B9 | C10: =B10/B16*C16 | D10: =C10/C16*D16 | E10: =D10/D16*E16 | F10: =E10/E16*F16 | K10: =SUM(C10:I10)-B10
A11: 3.加工费 | B11: 203905 | C11: =B11/B16*C16 | D11: =C11/C16*D16 | E11: =D11/D16*E16 | F11: =E11/E16*F16 | K11: =SUM(C11:I11)-B11 | L11: =B5/材料!J5*P11 | O11: 90 | P11: =Q11/O11 | Q11: 63716.81
A12: 4.劳动保护费
A13: 5.物料费
A14: 6.燃油费 | M14: 成本率
A15: 7.其他费用 | L15: =生产成本月结表!H11 | M15: 材料接近0
A16: 总成本合计 | B16: =销售成本!G12 | C16: =销售成本!G5 | D16: =销售成本!G6 | E16: =销售成本!G7 | F16: =销售成本!G8 | K16: =SUM(C16:I16)-B16 | L16: =生产成本月结表!F20 | M16: 废料接近0 | N16: 废料太低（负数）降低加工费
A17: 单位 | C17: 千克 | D17: 套 | E17: 付 | F17: 套
A18: 产成品数量 | B18: =销售成本!F12 | C18: =销售成本!F5 | D18: =销售成本!F6 | E18: =销售成本!F7 | F18: =销售成本!F8 | K18: =SUM(C18:I18)-B18
A19: 平均单价 | C19: =C16/C18 | D19: =D16/D18 | E19: =E16/E18 | F19: =F16/F18
B22: =SUM(C22:F22) | C22: =C5/材料!$J$5*1000 | D22: =D5/材料!$J$5*1000 | E22: =E5/材料!$J$5*1000
C23: =C22-C18 | D23: =D22/D18 | E23: =E22/E18 | J23: 公斤
B24: =测算表!G25*产品成本!B25
A25: 料率 | B25: =B5/B16 | C25: 0.84093418
A26: 工资率 | B26: =B7/B16 | C26: 0.065046991
A27: 动力率 | B27: =B9/B16 | C27: 0.0157
A28: 加工 | B28: =B11/B16 | C28: 0.077704789 | D28: =产品成本!B16*0.042

Sheet 材料
A1: 原 材 料 进 销 存 月 结 表 | S1: =生产成本月结表!J4
A2: 编制单位：揭阳市揭东区磐东洪运来机械厂 2025 年 12 月份 单位：人民币元 | S2: =生产成本月结表!J5
A3: 品名 | B3: 单位 | C3: 上月结存 | F3: 本月进仓数 | I3: 本月发出数 | L3: 本月结余 | O3: 备注 | S3: =生产成本月结表!F20
C4: 数量 | D4: 单价 | E4: 金额 | F4: 数量 | G4: 单价 | H4: 金额 | I4: 数量 | J4: 单价 | K4: 金额 | L4: 数量 | M4: 单价 | N4: 金额
A5: 带钢 | B5: 吨 | F5: =14.2+18.23 | G5: =H5/F5 | H5: =49262.83+63242.48 | I5: 32.43 | J5: =(E5+H5)/(C5+F5) | K5: =I5*J5 | L5: =C5+F5-I5 | M5: =N5/L5 | N5: =E5+H5-K5 | Q5: =91.247-91.247 | R5: =S5/Q5 | S5: =380000-380000
A6: 冷轧带钢 | B6: 吨 | F6: =153.837+44.435 | G6: =H6/F6 | H6: =485337.17+137632.74 | I6: 119.5 | J6: =(E6+H6)/(C6+F6) | K6: =I6*J6 | L6: =C6+F6-I6 | M6: =N6/L6 | N6: =E6+H6-K6 | U6: =S1/J6
A7: 冷轧卷板 | B7: 吨 | C7: 77.517 | D7: =E7/C7 | E7: 245865.33 | I7: =C7 | J7: =(E7+H7)/(C7+F7) | K7: =I7*J7 | L7: =C7+F7-I7 | M7: =N7/L7 | N7: =E7+H7-K7
A8: 钢珠 | B8: 千克 | C8: 172.195 | D8: =E8/C8 | E8: 995.3 | F8: =6153.231 | G8: =H8/F8 | H8: =35394.69 | I8: 1610 | J8: =(E8+H8)/(C8+F8) | K8: =I8*J8 | L8: =C8+F8-I8 | M8: =N8/L8 | N8: =E8+H8-K8 | T8: 37.5
A9: 滑轨塑料配件 | B9: 套 | C9: 47181 | D9: =E9/C9 | E9: 22964.38 | F9: 45454 | G9: =H9/F9 | H9: 22123.89 | I9: 31720 | J9: =(E9+H9)/(C9+F9) | K9: =I9*J9 | L9: =C9+F9-I9 | M9: =N9/L9 | N9: =E9+H9-K9 | R9: 物料 | U9: =V9/J8 | V9: =产品成本!B16*0.05
A10: 润滑脂 | B10: 桶 | U10: =V10/J9 | V10: =产品成本!B16*0.03
A11: 纸箱 | B11: 个 | C11: 2263 | D11: =E11/C11 | E11: 6007.77 | F11: 6532 | G11: =H11/F11 | H11: 17341.59 | I11: 3500 | J11: =(E11+H11)/(C11+F11) | K11: =I11*J11 | L11: =C11+F11-I11 | M11: =N11/L11 | N11: =E11+H11-K11 | U11: =V11/J10 | V11: =产品成本!B16*0.02
A12: 卡板托盘 | B12: 套
A13: 胶带 | B13: 平方米
A14: 废料 | B14: 吨 | F14: 87.011315 | G14: =H14/F14 | H14: =210408.76/1.13*0.95502022 | L14: =C14+F14-I14 | M14: =N14/L14 | N14: =E14+H14-K14
A16: 合 计 | C16: =SUM(C5:C15) | E16: =SUM(E5:E15) | F16: =SUM(F5:F15) | H16: =SUM(H5:H15) | I16: =SUM(I5:I15) | K16: =SUM(K5:K15) | L16: =SUM(L5:L15) | N16: =SUM(N5:N15) | O16: =S5
J17: =SUM(K15:K15)/(SUM(I15:I15)+(I8+I6)/1000)
F18: 58369.933 | H18: 810335.39
F19: =F18-F16 | H19: =H18-H16
I20: =SUM(I5:I12) | J20: =K20/I20 | K20: =SUM(K5:K12) | N20: =测算表!G13/0.13-N16
I24: 钢珠 | J24: 0.015 | K24: =J24*产品成本!$B$16/J8
I25: 滑轨塑料配件 | J25: 0.025 | K25: =J25*产品成本!$B$16/J9
I26: 润滑脂 | J26: 0.007 | K26: =J26*产品成本!$B$16/J10
I27: 纸箱 | J27: 0.015 | K27: =J27*产品成本!$B$16/J11
I28: 卡板托盘 | J28: 0.02 | K28: =J28*产品成本!$B$16/J12

Sheet 测算表
A1: 销售废料0元 | E1: =B2+D4 | H1: 含税 | I1: 金额 | J1: 税额
A2: 收入 | B2: =销售成本!E12+H7 | G2: 冲减无票销售 | J2: =H2-I2 | K2: =H2/1.13
A3: 成本 | B3: =销售成本!J12+K7 | C3: 增值税 | D3: =(D4-F4-F5)
C4: 销项 | D4: 109499.64 | E4: 进项 | F4: =F13 | H4: =生产成本月结表!J4
A5: 生产成本 | B5: =B6+B7+B8 | E5: 留抵
A6: 1.材料 | B6: =产品成本!B5 | H6: 金额 | I6: 税额 | J6: 含税
A7: 1.工资 | B7: 75100 | E7: =生产成本月结表!J5 | G7: 废铁 | J7: =H7+I7 | K7: =废料!X119*0
A8: 3.制造费用 | B8: =B9+B10+B11 | G8: 开票销售 | J8: =H8+I8
A9: 3.1折旧 | B9: 3567.6 | D9: 期初电 | E9: 期末电 | G9: 无票销售 | H9: =H10-H7-H8 | I9: =I10-I7-I8 | J9: =J10-J7-J8
A10: 3.2电费 | B10: =电费!E64 | D10: =生产成本月结表!B6 | E10: =生产成本月结表!E6
A11: 3.3加工费 | B11: =产品成本!B11-生产成本月结表!B8
D12: 期初待抵 | E12: 本期增加 | F12: 本期认证 | G12: 期末留抵
A13: 主营业务税金及附加 | B13: =B14+B15+B16+B17 | D13: 89965.29 | E13: =E14+1088.48+68.72+103.08 | F13: 93998.6 | G13: =D13+E13-F13
A14: 1.城建税 | B14: =D3*0.07/2-0.01 | E14: 105343.61
A15: 2.教育费附加 | B15: =IF(B2<100000,0,D3*0.03/2)-0.01 | G15: 102570.58 | H15: =G13-G15
A16: 3.地方教育费附加 | B16: =IF(B2<100000,0,D3*0.02/2)
D17: 年销售额 | E17: =E28/12*12
A18: 销售费用 | B18: =SUM(B19:B21) | D18: 年利润总额 | E18: 222369.28
A19: 出口服务费 | B19: 1908 | D19: 投资者减除
A20: 报关费 | B20: =721+1884.9 | D20: 应纳税所得额 | E20: =E18-E19
A21: 运输费 | B21: =6872+10308 | D21: 应纳税额 | E21: =IF(E20<=30000,E20*0.05,IF(E20<=90000,E20*0.1-1500,IF(E20<=300000,E20*0.2-10500,IF(E20<=500000,E20*0.3-40500,E20*0.35-65500))))
D22: 减免税额 | E22: =E21/2 | F22: =E22/E17 | G22: =E17*0.00206870879425307-E22
A23: 营业利润 | B23: =B2-B3-B13-B18 | D23: 已缴纳税额 | E23: =1366.83+2284.43+5819.66
D24: 缓交税额
A25: 管理费用 | B25: =SUM(B26:B35) | D25: 应补税额 | E25: =E21-E22-E23-E24 | G25: 0.99385816
A26: 1.工资 | B26: 5000 | I26: 税款
A27: 2.办公 | I27: =D3+B14+B15+B16+B35+E38
A28: 3.差旅 | D28: 累计销售额 | E28: =生产成本月结表!B14
A29: 4.业务 | D29: 利润总额 | E29: =E18/12*12
A30: 5.保险 | D30: 实际利润总额 | E30: =203838.52+B47 | G30: =E28-E30
A31: 6.折旧 | D31: 差异 | E31: =E30-E29
A32: 7.福利费 | D32: 投资者减除
A33: 8.土地使用税 | C33: 7500 | D33: 应纳税所得额 | E33: =E30-E32
A34: 9.房产税 | C34: 3746.4 | D34: 应纳税额 | E34: =IF(E33<=30000,E33*0.05,IF(E33<=90000,E33*0.1-1500,IF(E33<=300000,E33*0.2-10500,IF(E33<=500000,E33*0.3-40500,E33*0.35-65500))))
A35: 10.社保费 | B35: 8623.65 | D35: 减免税额 | E35: =E34/2 | F35: =E35/E28
D36: 已缴纳税额 | E36: =E23
A37: 财务费用 | B37: =B39-B38+B40+B41-B42 | D37: 缓交税额 | E37: =E24
A38: 利息 | B38: 50.08 | D38: 应补税额 | E38: =E34-E35-E36-E37
A39: 手续费 | B39: =2.5+94.5+10 | E39: =E25-E38
A40: 贷款息 | B40: 3150
...

Sheet 工资
A1: 揭阳市揭东区磐东洪运来机械厂
A2: 2025年12月工资计算表
B3: 货币单位:元
A4: 部门名称 | B4: 应发金额
A5: 生产车间 | B5: =测算表!B7
A6: 管理部门 | B6: =测算表!B26
A7: 合 计 | B7: =B5+B6
B11: =B5/4500

Sheet 生产成本月结表
A1: 生产成本月结表
A2: 编制单位：揭阳市揭东区磐东洪运来机械厂 2025 年 12 月份 单位：元
A3: 项目 | B3: 上月结存 | C3: 本月发生 | D3: 本月结转 | E3: 本月结余 | F3: 备注
A4: 材料费 | B4: 177431.24 | C4: =材料!K16-材料!S9 | D4: =产品成本!B5+测算表!K7+材料!H14 | E4: =B4+C4-D4 | F4: =E4/E9 | G4: =产品成本!B25 | J4: =E6/(G6/G4)-E4
A5: 工资 | B5: 26088.3 | C5: =测算表!B7 | D5: =产品成本!B7 | E5: =B5+C5-D5 | F5: =E5/E9 | G5: =产品成本!B26 | J5: =E6/(G6/G5)-E5
A6: 动力 | B6: 2376.3 | C6: =测算表!B10 | D6: =产品成本!B9 | E6: =B6+C6-D6 | F6: =E6/E9 | G6: =产品成本!B27
A7: 折旧 | C7: =测算表!B9 | D7: =产品成本!B10
A8: 加工 | C8: =测算表!B11 | D8: =产品成本!B11
A9: 合 计 | B9: =SUM(B4:B8) | C9: =SUM(C4:C8) | D9: =SUM(D4:D8) | E9: =SUM(E4:E8)
H11: =G12-H12
G12: =E4+材料!N16 | H12: =F14*产品成本!B24
E13: =E9+材料!N16+销售成本!L12*0
A14: 累计销售额 | B14: =7527087+测算表!B2 | D14: =材料!O16 | E14: =E13/0.71947*0.13 | F14: =E14/0.13 | G14: =F14*C15
A15: 实缴 | B15: =169486.28+测算表!D3 | C15: =B15/B14 | D15: =D14*0.13 | E15: =测算表!G13
A16: 应缴 | B16: =B14*0.0221 | E16: =E14-E15
A17: 多交 | B17: =B15-B16
H18: =H11-F20
D19: =E16-D15
E20: =G14-B17-D19 | F20: =E20/0.13 | G20: 少结材料 | H20: 开票单价提高
G21: 废料

Sheet 付工资
A1: 揭阳市揭东区磐东洪运来机械厂
A2: 工 资 表
E4: 单位：元 2025年11月
A6: 序号 | B6: 姓 名 | C6: 应发工资 | D6: 扣 款 | E6: 实发工资 | F6: 签 名 | J6: 姓名 | M6: 姓 名 | N6: 应发工资
B7: 李洪军 | C7: 2800 | D7: 0 | E7: =C7-D7 | I7: 1 | J7: 李洪军 | M7: 曾小琼 | N7: 6550
B8: 李静 | C8: 2200 | D8: 0 | E8: =C8-D8 | I8: 2 | J8: 李静 | M8: 陈云凤 | N8: 8840
B9: 杨泽明 | C9: 8840 | D9: 0 | E9: =C9-D9 | H9: =C9-1000 | I9: 3 | J9: 杨泽明 | M9: 代飞 | N9: 6270
B10: 余文平 | C10: 8080 | D10: 0 | E10: =C10-D10 | H10: =C10-1000 | I10: 4 | J10: 余文平 | M10: 代燕 | N10: 7470
B11: 陈云凤 | C11: 8840 | D11: 0 | E11: =C11-D11 | H11: =C11-1000 | I11: 5 | J11: 陈云凤 | M11: 代玉金 | N11: 8970
B12: 代玉金 | C12: 8970 | D12: 0 | E12: =C12-D12 | H12: =C12-1000 | I12: 6 | J12: 代玉金 | M12: 郭聪 | N12: 7750
B13: 杨艳群 | C13: 8860 | D13: 0 | E13: =C13-D13 | H13: =C13-1000 | I13: 7 | J13: 杨艳群 | M13: 李洪军 | N13: 2800
B14: 李金容 | C14: 7940 | D14: 0 | E14: =C14-D14 | H14: =C14-1000 | I14: 8 | J14: 李金容 | M14: 李金容 | N14: 7940
B15: 张贵华 | C15: 7680 | D15: 0 | E15: =C15-D15 | H15: =C15-1000 | I15: 9 | J15: 张贵华 | M15: 李静 | N15: 2200
B16: 王彬 | C16: 7320 | D16: 0 | E16: =C16-D16 | H16: =C16-1000 | I16: 10 | J16: 王彬 | M16: 刘华清 | N16: 6310
B17: 代燕 | C17: 7470 | D17: 0 | E17: =C17-D17 | H17: =C17-1000 | I17: 11 | J17: 代燕 | M17: 石光成 | N17: 6920
B18: 郭聪 | C18: 7750 | D18: 0 | E18: =C18-D18 | H18: =C18-1000 | I18: 12 | J18: 郭聪 | M18: 王彬 | N18: 7320
B19: 吴文荣 | C19: 7380 | D19: 0 | E19: =C19-D19 | H19: =C19-1000 | I19: 13 | J19: 吴文荣 | M19: 吴文荣 | N19: 7380
B20: 石光成 | C20: =7820-900 | D20: 0 | E20: =C20-D20 | H20: =C20-1000 | I20: 14 | J20: 石光成 | M20: 杨艳群 | N20: 8860
B21: 曾小琼 | C21: 6550 | D21: 0 | E21: =C21-D21 | H21: =C21-1000 | I21: 15 | J21: 曾小琼 | M21: 杨泽明 | N21: 8840
B22: 叶书香 | C22: 6560 | D22: 0 | E22: =C22-D22 | H22: =C22-1000 | I22: 16 | J22: 叶书香 | M22: 叶书香 | N22: 6560
B23: 代飞 | C23: 6270 | D23: 0 | E23: =C23-D23 | H23: =C23-1000 | I23: 17 | J23: 代飞 | M23: 余文平 | N23: 8080
B24: 刘华清 | C24: 6310 | D24: 0 | E24: =C24-D24 | H24: =C24-1000 | I24: 18 | J24: 刘华清 | M24: 张贵华 | N24: 7680
I25: 19 | J25: 谢苏玲
I26: 20 | J26: 钟玉婷
J27: 郑华强
J28: 郑文益
A29: 合 计 | C29: =SUM(C7:C28) | D29: =SUM(D7:D28) | E29: =SUM(E7:E28) | J29: 杨玲
J30: 杨玉银
C31: =126740-C29 | J31: 石珠福

Sheet 电费
B3: 2022年洪运来电费
B4: 月份 | C4: 度数（KWH） | D4: 单价 | E4: 金额（不含税 | F4: 税额 | G4: 金额（含税
B5: 1 | C5: 5962 | D5: =E5/C5 | E5: 4680 | G5: =E5+F5
B6: 2 | C6: 8344 | D6: =E6/C6 | E6: 6550 | G6: =E6+F6
B7: 3 | C7: 17771 | D7: =E7/C7 | E7: 13950 | G7: =E7+F7
B8: 4 | C8: 6408 | D8: =E8/C8 | E8: 5030 | G8: =E8+F8
B9: 5 | C9: 6268 | D9: =E9/C9 | E9: 4920 | G9: =E9+F9
B10: 6 | C10: 19465 | D10: =E10/C10 | E10: 15280 | G10: =E10+F10
B11: 7 | C11: 16917 | D11: =E11/C11 | E11: 13280 | G11: =E11+F11
B12: 8 | C12: 22739 | D12: =E12/C12 | E12: 17850 | G12: =E12+F12
B13: 9 | C13: 20280 | D13: =E13/C13 | E13: 15920 | G13: =E13+F13
B14: 10 | C14: 12637 | D14: =E14/C14 | E14: 9920 | G14: =E14+F14
A15: 付10月电费 | B15: 11 | C15: 22395 | D15: =E15/C15 | E15: 17580 | G15: =E15+F15
A16: 付11月电费 | B16: 12 | C16: 22624 | D16: =E16/C16 | E16: 17760 | G16: =E16+F16
C17: =SUM(C5:C16) | D17: =E17/C17 | E17: =SUM(E5:E16) | F17: =SUM(F5:F16) | G17: =SUM(G5:G16)
B19: 2023年洪运来电费
B20: 月份 | C20: 度数（KWH） | D20: 单价 | E20: 金额（不含税 | F20: 税额 | G20: 金额（含税
A21: 付12月电费 | B21: 1 | C21: 13452 | D21: =E21/C21 | E21: 10560 | G21: =E21+F21
A22: 付1月电费 | B22: 2 | C22: 12076 | D22: =E22/C22 | E22: 9480 | G22: =E22+F22
A23: 付2月电费 | B23: 3 | C23: 7465 | D23: =E23/C23 | E23: 5860 | G23: =E23+F23
A24: 付3月电费 | B24: 4 | C24: 27322 | D24: =E24/C24 | E24: 23920 | G24: =E24+F24
A25: 付4月电费 | B25: 5 | C25: 9580 | D25: =E25/C25 | E25: 9772 | G25: =E25+F25
A26: 付5月电费 | B26: 6 | C26: 17245 | D26: =E26/C26 | E26: 17590 | G26: =E26+F26
A27: 付6月电费 | B27: 7 | C27: 8108 | D27: =E27/C27 | E27: 8270 | G27: =E27+F27
A28: 付7月电费 | B28: 8 | C28: 5716 | D28: =E28/C28 | E28: 5830 | G28: =E28+F28
A29: 付8月电费 | B29: 9 | C29: 8657 | D29: =E29/C29 | E29: 8830 | G29: =E29+F29
A30: 付9月电费 | B30: 10 | C30: 6152 | D30: =E30/C30 | E30: 6275 | G30: =E30+F30
A31: 付10月电费 | B31: 11 | C31: 6647 | D31: =E31/C31 | E31: 6780 | G31: =E31+F31 | I31: 3693.6 | J31: =K31/I31 | K31: 2667.77
A32: 付11月电费 | B32: 12 | C32: 6398 | D32: =E32/C32 | E32: 6525.96 | G32: =E32+F32 | I32: 14638.8 | J32: =K32/I32 | K32: 10559.97
C33: =SUM(C21:C32) | D33: =E33/C33 | E33: =SUM(E21:E32) | F33: =SUM(F21:F32) | G33: =SUM(G21:G32) | L33: 当月月头
L34: 揭阳市揭东区磐东洪运来机械厂
B35: 2024年洪运来电费 | L35: 上月电费 度*0.785元/度=
B36: 月份 | C36: 度数（KWH） | D36: 单价 | E36: 金额（不含税 | F36: 税额 | G36: 金额（含税 | M36: 李
A37: 付12月电费 | B37: 1 | C37: 19500 | D37: =E37/C37 | E37: 14296.79 | G37: =E37+F37 | I37: =C37*50
A38: 付1月电费 | B38: 2 | C38: 13535.6 | D38: =E38/C38 | E38: 8560.59 | F38: 1112.88 | G38: =E38+F38 | I38: =C38*50
A39: 付2月电费 | B39: 3 | C39: 2168 | D39: =E39/C39 | E39: 1406.83 | F39: 182.89 | G39: =E39+F39 | I39: =C39*50
A40: 付3月电费 | B40: 4 | C40: 15748 | D40: =E40/C40 | E40: 10058.77 | F40: 1307.64 | G40: =E40+F40 | I40: =C40*50
A41: 付4月电费 | B41: 5 | C41: 15079.6 | D41: =E41/C41 | E41: 9633.17 | F41: 1252.31 | G41: =E41+F41 | I41: =C41*50
A42: 付5月电费 | B42: 6 | C42: 15882.8 | D42: =E42/C42 | E42: 10147.67 | F42: 1319.2 | G42: =E42+F42 | I42: =C42*50
A43: 付6月电费 | B43: 7 | C43: 12502.8 | D43: =E43/C43 | E43: 7645.17 | F43: 993.87 | G43: =E43+F43 | I43: =C43*50
...

Sheet 废料
B2: 品名 | C2: 单位 | D2: 上月结存 | G2: 本月进仓数 | J2: 本月发出数 | M2: 本月结余 | P2: 备注
D3: 数量 | E3: 单价 | F3: 金额 | G3: 数量 | H3: 单价 | I3: 金额 | J3: 数量 | K3: 单价 | L3: 金额 | M3: 数量 | N3: 单价 | O3: 金额
B4: 带钢 | C4: 吨 | D4: 89.063 | E4: 3913.4375 | F4: 348542.48 | G4: 178.262 | H4: 3720.7936 | I4: 663276.11 | J4: 180.64 | K4: 3784.9756 | L4: 683717.98 | M4: 86.685 | N4: 3784.9756 | O4: 328100.61 | P4: 5月
B5: 镀铝锌卷板 | C5: 吨 | G5: 7.745 | H5: 4010.581 | I5: 31061.95 | J5: 7.745 | K5: 4010.581 | L5: 31061.95 | M5: 0 | N5: #DIV/0! | O5: 0 | P5: 5月
J12: =SUM(J4:J7) | K12: =L12/J12 | L12: =SUM(L4:L7) | O12: =测算表!H20/0.13-O8
J13: =J12*0.09 | K13: 2930 | L13: =J13*K13
I17: 废料销售 | J17: 7 | K17: 2700 | L17: 18900 | M17: 4月未销售废料
I18: 废料销售 | J18: 18.5 | K18: 2886.0503 | L18: 53391.93 | M18: 5月未销售废料
I19: 废料销售 | J19: 3.375 | K19: 2834.9778 | L19: 9568.0502 | M19: 6月未销售废料
I20: 废料销售 | J20: 1.7919 | K20: 2834.9778 | L20: 5079.9968 | M20: 7月未销售废料
I21: 废料销售 | J21: 6.42321 | K21: 2834.9778 | L21: 18209.66 | M21: 8月未销售废料
I22: 废料销售 | J22: 10.06848 | K22: =L22/J22 | L22: 28543.92 | M22: 9月未销售废料
I23: 废料销售 | J23: 10.22121 | K23: 2834.9778 | L23: 28976.9 | M23: 10月未销售废料
I24: 废料销售 | J24: 16.785 | K24: =L24/J24 | L24: 47585.11 | M24: 11月未销售废料
I25: 废料销售 | J25: 19.075 | K25: =L25/J25 | L25: 62937.05 | M25: 12月未销售废料
J27: =SUM(J17:J26) | K27: =2930 | L27: =SUM(L17:L26) | N27: =L27/1.13 | O27: =生产成本月结表!F11
L28: =J27*K27-L17-L18-L19-L20-L21-L22-L23-L24 | O28: =N27-O27
J30: 85.324 | K30: =L30/J30 | L30: 250000 | N30: =L30/1.13
I31: 废料销售 | J31: =J27-J30 | K31: =L31/J31 | L31: =L27-L30 | M31: 12月未销售废料 | N31: =L31/1.13 | O31: =N31*0.964963653865046
I32: 废料销售 | J32: 16.84593 | K32: =L32/J32 | L32: 49358.575 | M32: 1月未销售废料 | N32: =L32/1.13 | O32: =N32*0.964963653865046
I33: 废料销售 | J33: 10.01151 | K33: =L33/J33 | L33: =29333.7243+0.68 | M33: 2月未销售废料 | N33: =L33/1.13 | O33: =N33*0.964963653865046
I34: 废料销售 | J34: 9.83223 | K34: 2930 | L34: 28808.434 | M34: 3月未销售废料 | N34: =L34/1.13 | O34: =N34*0.964963653865046
I35: 废料销售 | J35: 6.52545 | K35: 2930 | L35: 19119.569 | M35: 4月未销售废料 | N35: =L35/1.13 | O35: =N35*0.964963653865046
I36: 废料销售 | J36: 16.95465 | K36: 2930 | L36: 49677.124 | M36: 5月未销售废料 | N36: =L36/1.13 | O36: =N36*0.964963653865046
J39: =SUM(J31:J38) | K39: 2930 | L39: =SUM(L31:L38) | N39: =SUM(N31:N38) | O39: =SUM(O31:O38)
L40: =J39*K39-L31-L32-L33-L34-L35 | O40: =N39-O39
I42: 预测废料 | J42: =J27-J30+J39 | K42: =L42/J42 | L42: =L27-L30+L39
R45: 以上废料已结算
U47: 数量 | V47: 单价 | W47: 金额 | X47: 税额 | Y47: 含税金额
B48: 品名 | C48: 单位 | D48: 上月结存 | G48: 本月进仓数 | J48: 本月发出数 | M48: 本月结余 | P48: 备注 | R48: 45467 | S48: *金属制品*废铁 | T48: 吨 | U48: 68.259 | V48: =W48/U48 | W48: 176991.15 | X48: 23008.85 | Y48: 200000
D49: 数量 | E49: 单价 | F49: 金额 | G49: 数量 | H49: 单价 | I49: 金额 | J49: 数量 | K49: 单价 | L49: 金额 | M49: 数量 | N49: 单价 | O49: 金额 | V49: =Y48/U48
B50: 带钢 | C50: 吨 | D50: 86.685 | E50: 3784.9756 | F50: 328100.61 | G50: 75.48 | H50: 3820.2349 | I50: 288351.33 | J50: 102.786 | K50: 3801.3871 | L50: 390729.38 | M50: 59.379 | N50: 3801.3871 | O50: 225722.56 | P50: 6月
B51: 镀锌带钢 | C51: 吨 | G51: 8.234 | H51: 4309.7802 | I51: 35486.73 | J51: 8.234 | K51: 4309.7802 | L51: 35486.73 | M51: 0 | N51: #DIV/0! | O51: 0 | P51: 6月
B52: 带钢 | C52: 吨 | D52: 59.379 | E52: 3801.387 | F52: 225722.56 | G52: 259.376 | H52: 3828.8215 | I52: 993104.41 | J52: 79 | K52: 3823.7109 | L52: 302073.16 | M52: 239.755 | N52: 3823.7109 | O52: 916753.81 | P52: 7月
B53: 带钢 | C53: 吨 | D53: 239.755 | E53: 3823.7109 | F53: 916753.81 | G53: 104.677 | H53: 3678.9109 | I53: 385097.36 | J53: 106.6 | K53: 3779.7045 | L53: 402916.5 | M53: 237.832 | N53: 3779.7045 | O53: 898934.67 | P53: 8月
B54: 镀锌带钢 | C54: 吨 | D54: 9.086 | E54: 4310.044 | F54: 39161.06 | J54: 9.086 | K54: 4310.044 | L54: 39161.06 | M54: 0 | N54: #DIV/0! | O54: 0 | P54: 8月
B55: 冷轧板卷 | C55: 吨 | D55: 10.448 | E55: 3913.0159 | F55: 40883.19 | J55: 10.448 | K55: 3913.0159 | L55: 40883.19 | M55: 0 | N55: #DIV/0! | O55: 0 | P55: 8月 | R55: 2024.10.26 | S55: *金属制品*废铁 | T55: 吨 | U55: 11.54 | V55: =W55/U55 | W55: 26548.67 | X55: 3451.33 | Y55: 30000
B56: 带钢 | C56: 吨 | D56: 237.832 | E56: 3779.7045 | F56: 898934.67 | G56: 56.07 | H56: 3650.7621 | I56: 204698.23 | J56: 154.8 | K56: 3755.1051 | L56: 581290.27 | M56: 139.102 | N56: 3755.1051 | O56: 522342.63 | P56: 9月 | V56: =Y55/U55 | W56: =W55/N65*O65
G63: =K64*1.13
G64: =K65/G63 | J64: =SUM(J50:J59) | K64: =L64/J64 | L64: =SUM(L50:L59)
...

Sheet 加工成本
A1: 揭阳市揭东区磐东洪运来机械厂
A2: 加工成本计算表
A3: 项 目 | B3: 数量 | C3: 单位 | D3: 单位成本 | E3: 合 计
A4: 工 资 | C4: 吨 | D4: 323
A5: 制造费用 | C5: 吨 | D5: 645 | E5: =E12*0.45149*0.954
A6: 总 计 | B6: =B4 | D6: 968 | E6: =E4+E5
A12: 加工收入： | E12: =E11/1.17
A14: 加工利润 | E14: =E12-E6
A16: 毛利率 | E16: =E14/E12
