Workbook

Sheet 销售成本
A1: 产品销售成本计算表
A2: 编制单位：揭阳市揭东区磐东洪运来机械厂 2025年11月 单位:元
A3: 品名 项目 | B3: 期初库存 | D3: 本期销售 | F3: 本期生产 | H3: 本月销售成本 | K3: 期末库存
B4: 数量 | C4: 金额 | D4: 数量 | E4: 金额 | F4: 数量 | G4: 金额 | H4: 数量 | I4: 单价 | J4: 金额 | K4: 数量 | L4: 金额 | N4: 销售单价 | R4: 报关 | S4: 数量 | T4: 金额 | U4: 订单 | V4: 成本
A5: 铁制导轨（千克 | B5: 39659.65 | C5: 280473.77 | D5: 117797.64 | E5: 899979.53 | F5: =S5 -> 158313.76 | G5: =E5/D5*D5*测算表!$G$25*0+V5 -> 1140701 | H5: =D5 -> 117797.64 | I5: =(C5+G5)/(B5+F5) -> 7.1786146 | J5: =H5*I5 -> 845623.85 | K5: =B5+F5-H5 -> 80175.77 | L5: =C5+G5-J5 -> 575550.95 | N5: =E6/D6 -> 3.4833204 | R5: 铁制导轨（千克 | S5: =37691.85+40446.14+39755.65+40420.12 -> 158313.76 | T5: =284579.9+316238.53+301852.32+315439.03 -> 1218109.8 | U5: -72-73-74-75 | V5: =T5*测算表!$G$25 -> 1140701
A6: 滑轨（付 | D6: 35005 | E6: 121933.63 | F6: =D6-B6 -> 35005 | G6: =E6/D6*F6*测算表!$G$25 -> 114184.96 | H6: =D6 -> 35005 | I6: =(C6+G6)/(B6+F6) -> 3.2619615 | J6: =H6*I6 -> 114184.96 | K6: =B6+F6-H6 -> 0 | L6: =C6+G6-J6 -> 0 | N6: =E7/D7 -> 7.7968097
A7: 三节滑轨（付 | D7: 5849 | E7: 45603.54 | F7: =D7-B7 -> 5849 | G7: =E7/D7*F7*测算表!$G$25 -> 42705.515 | H7: =D7 -> 5849 | I7: =(C7+G7)/(B7+F7) -> 7.3013361 | J7: =H7*I7 -> 42705.515 | K7: =B7+F7-H7 -> 0 | L7: =C7+G7-J7 -> 0 | N7: =E10/D10 -> #DIV/0!
S9: =SUM(S5:S8) -> 158313.76 | T9: =SUM(T5:T8) -> 1218109.8 | U9: =T9/S9 -> 7.6942761 | V9: =SUM(V5:V8) -> 1140701
A12: 合 计 | B12: =SUM(B5:B11) -> 39659.65 | C12: =SUM(C5:C11) -> 280473.77 | D12: =SUM(D5:D11) -> 158651.64 | E12: =SUM(E5:E11) -> 1067516.7 | F12: =SUM(F5:F11) -> 199167.76 | G12: =SUM(G5:G11) -> 1297591.5 | H12: =SUM(H5:H11) -> 158651.64 | J12: =SUM(J5:J11) -> 1002514.3 | K12: =SUM(K5:K11) -> 80175.77 | L12: =SUM(L5:L11) -> 575550.95
J14: =H10*I10 -> 0
E17: =E6+E7 -> 167537.17

Sheet 产品成本
A1: 产 品 成 本 核 算 表
A2: 编制单位:揭阳市揭东区磐东洪运来机械厂 2025.11 单位:元
A3: 项目 品名 | B3: 总计金额 | C3: =销售成本!A5 -> 铁制导轨（千克 | D3: =销售成本!A6 -> 滑轨（付 | E3: =销售成本!A7 -> 三节滑轨（付 | L3: =生产成本月结表!J4 -> -2014.4757 | M3: =生产成本月结表!E4-测算表!K7 -> 177431.24
A4: 一、直接计入 | B4: =B5+B7 -> 1077412.1 | C4: =C5+C7 -> 947143.26 | D4: =D5+D7 -> 94809.695 | E4: =E5+E7 -> 35459.108 | K4: =SUM(C4:I4)-B4 -> 0 | L4: =生产成本月结表!J5 -> -19.184063
A5: 1.原材料 | B5: =B16-B8-B7 -> 938011.81 | C5: =B5/B16*C16 -> 824597.75 | D5: =C5/C16*D16 -> 82542.804 | E5: =D5/D16*E16 -> 30871.254 | K5: =SUM(C5:I5)-B5 -> 0 | L5: =生产成本月结表!E6 -> 2376.2958 | M5: 动力余额
A6: 2.包装物
A7: 3.工资及福利 | B7: =B16*0.10743 -> 139400.26 | C7: =B7/B16*C16 -> 122545.51 | D7: =C7/C16*D16 -> 12266.89 | E7: =D7/D16*E16 -> 4587.8535 | K7: =SUM(C7:I7)-B7 -> 0
A8: 二、分配计入 | B8: =B9+B10+B11+B13 -> 220179.44 | C8: =C9+C10+C11+C13 -> 193557.77 | D8: =D9+D10+D11+D13 -> 19375.266 | E8: =E9+E10+E11+E13 -> 7246.4072 | K8: =SUM(C8:I8)-B8 -> 0 | O8: 加工费余额
A9: 1.水电费 | B9: =B16/65*电费!D63 -> 12706.844 | C9: =B9/B16*C16 -> 11170.473 | D9: =C9/C16*D16 -> 1118.172 | E9: =D9/D16*E16 -> 418.19966 | K9: =SUM(C9:I9)-B9 -> 0 | O9: =-25000+63716.81-B11 -> -165188.19
A10: 2.折旧费 | B10: =测算表!B9 -> 3567.6 | C10: =B10/B16*C16 -> 3136.2451 | D10: =C10/C16*D16 -> 313.9403 | E10: =D10/D16*E16 -> 117.41461 | K10: =SUM(C10:I10)-B10 -> 0
A11: 3.加工费 | B11: 203905 | C11: =B11/B16*C16 -> 179251.05 | D11: =C11/C16*D16 -> 17943.154 | E11: =D11/D16*E16 -> 6710.793 | K11: =SUM(C11:I11)-B11 -> 0 | L11: =B5/材料!J5*P11 -> 203905.51 | O11: 90 | P11: =Q11/O11 -> 707.96456 | Q11: 63716.81
A12: 4.劳动保护费
A13: 5.物料费
A14: 6.燃油费 | M14: 成本率
A15: 7.其他费用 | L15: =生产成本月结表!H11 -> 6.0230612 | M15: 材料接近0
A16: 总成本合计 | B16: =销售成本!G12 -> 1297591.5 | C16: =销售成本!G5 -> 1140701 | D16: =销售成本!G6 -> 114184.96 | E16: =销售成本!G7 -> 42705.515 | K16: =SUM(C16:I16)-B16 -> 0 | L16: =生产成本月结表!F20 -> 120106.76 | M16: 废料接近0
A17: 单位 | C17: 千克 | D17: 付 | E17: 付
A18: 产成品数量 | B18: =销售成本!F12 -> 199167.76 | C18: =销售成本!F5 -> 158313.76 | D18: =销售成本!F6 -> 35005 | E18: =销售成本!F7 -> 5849 | K18: =SUM(C18:I18)-B18 -> 0
A19: 平均单价 | C19: =C16/C18 -> 7.2053183 | D19: =D16/D18 -> 3.2619615 | E19: =E16/E18 -> 7.3013361
B22: =SUM(C22:F22) -> 288016.55 | C22: =C5/材料!$J$5*1000 -> 253192.76 | D22: =D5/材料!$J$5*1000 -> 25344.77 | E22: =E5/材料!$J$5*1000 -> 9479.0194
C23: =C22-C18 -> 94879.002 | D23: =D22/D18 -> 0.72403286 | E23: =E22/E18 -> 1.6206222 | J23: 公斤
B24: =测算表!G25*产品成本!B25 -> 0.67694863
A25: 料率 | B25: =B5/B16 -> 0.72288683 | C25: 0.84093418
A26: 工资率 | B26: =B7/B16 -> 0.10743 | C26: 0.065046991
A27: 动力率 | B27: =B9/B16 -> 0.0097926382 | C27: 0.0157
A28: 加工 | B28: =B11/B16 -> 0.15714113 | C28: 0.077704789 | D28: =产品成本!B16*0.042 -> 54498.843

Sheet 材料
A1: 原 材 料 进 销 存 月 结 表 | S1: =生产成本月结表!J4 -> -2014.4757
A2: 编制单位：揭阳市揭东区磐东洪运来机械厂 2025 年 11 月份 单位：人民币元 | S2: =生产成本月结表!J5 -> -19.184063
A3: 品名 | B3: 单位 | C3: 上月结存 | F3: 本月进仓数 | I3: 本月发出数 | L3: 本月结余 | O3: 备注 | S3: =生产成本月结表!F20 -> 120106.76
C4: 数量 | D4: 单价 | E4: 金额 | F4: 数量 | G4: 单价 | H4: 金额 | I4: 数量 | J4: 单价 | K4: 金额 | L4: 数量 | M4: 单价 | N4: 金额
A5: 带钢 | B5: 吨 | F5: =13.544+11.933 -> 25.477 | G5: =H5/F5 -> 3256.7983 | H5: =44109.73+38863.72 -> 82973.45 | I5: =F5 -> 25.477 | J5: =(E5+H5)/(C5+F5) -> 3256.7983 | K5: =I5*J5 -> 82973.45 | L5: =C5+F5-I5 -> 0 | M5: =N5/L5 -> #DIV/0! | N5: =E5+H5-K5 -> 0 | Q5: =91.247-91.247 -> 0 | R5: =S5/Q5 -> #DIV/0! | S5: =380000-380000 -> 0
A6: 镀锌卷板 | B6: 吨 | F6: =8.508 -> 8.508 | G6: =H6/F6 -> 3681.3869 | H6: =31321.24 -> 31321.24 | I6: =F6 -> 8.508 | J6: =(E6+H6)/(C6+F6) -> 3681.3869 | K6: =I6*J6 -> 31321.24 | L6: =C6+F6-I6 -> 0 | M6: =N6/L6 -> #DIV/0! | N6: =E6+H6-K6 -> 0
A7: 冷轧带钢 | B7: 吨 | C7: 27.524 | D7: =E7/C7 -> 3184.988 | E7: 87663.61 | F7: =80.754 -> 80.754 | G7: =H7/F7 -> 3287.5985 | H7: =265486.73 -> 265486.73 | I7: =C7+F7 -> 108.278 | J7: =(E7+H7)/(C7+F7) -> 3261.5152 | K7: =I7*J7 -> 353150.34 | L7: =C7+F7-I7 -> 0 | M7: =N7/L7 -> #DIV/0! | N7: =E7+H7-K7 -> 0
A8: 冷轧板卷 | B8: 吨 | C8: 12.318 | D8: =E8/C8 -> 3615.3296 | E8: 44533.63 | I8: =C8 -> 12.318 | J8: =(E8+H8)/(C8+F8) -> 3615.3296 | K8: =I8*J8 -> 44533.63 | L8: =C8+F8-I8 -> 0 | M8: =N8/L8 -> #DIV/0! | N8: =E8+H8-K8 -> 0
A9: 冷轧卷板 | B9: 吨 | C9: 105.346 | D9: =E9/C9 -> 3165.4814 | E9: 333470.8 | F9: 41.671 | G9: =H9/F9 -> 3187.6331 | H9: =132831.86 -> 132831.86 | I9: 69.5 | J9: =(E9+H9)/(C9+F9) -> 3171.7601 | K9: =I9*J9 -> 220437.33 | L9: =C9+F9-I9 -> 77.517 | M9: =N9/L9 -> 3171.7601 | N9: =E9+H9-K9 -> 245865.33
A10: 塑料缓冲器配件 | B10: 个 | T10: 37.5
A11: 钢珠 | B11: 千克 | C11: 1282.195 | D11: =E11/C11 -> 5.7800881 | E11: 7411.2 | I11: 1110 | J11: =(E11+H11)/(C11+F11) -> 5.7800881 | K11: =I11*J11 -> 6415.8977 | L11: =C11+F11-I11 -> 172.195 | M11: =N11/L11 -> 5.7800881 | N11: =E11+H11-K11 -> 995.30226 | R11: 物料 | U11: =V11/J11 -> 11224.669 | V11: =产品成本!B16*0.05 -> 64879.576
A12: 滑轨塑料配件 | B12: 套 | C12: 68281 | D12: =E12/C12 -> 0.4867294 | E12: 33234.37 | I12: 21100 | J12: =(E12+H12)/(C12+F12) -> 0.4867294 | K12: =I12*J12 -> 10269.99 | L12: =C12+F12-I12 -> 47181 | M12: =N12/L12 -> 0.4867294 | N12: =E12+H12-K12 -> 22964.38 | U12: =V12/J12 -> 79978.209 | V12: =产品成本!B16*0.03 -> 38927.745
A13: 润滑脂 | B13: 桶 | C13: 37.79 | D13: =E13/C13 -> 213.09738 | E13: 8052.95 | I13: =C13 -> 37.79 | J13: =(E13+H13)/(C13+F13) -> 213.09738 | K13: =I13*J13 -> 8052.95 | L13: =C13+F13-I13 -> 0 | M13: =N13/L13 -> #DIV/0! | N13: =E13+H13-K13 -> 0 | U13: =V13/J13 -> 121.7839 | V13: =产品成本!B16*0.02 -> 25951.83
A14: 纸箱 | B14: 个 | F14: 10463 | G14: =H14/F14 -> 2.6547826 | H14: =27776.99 -> 27776.99 | I14: 8200 | J14: =(E14+H14)/(C14+F14) -> 2.6547826 | K14: =I14*J14 -> 21769.217 | L14: =C14+F14-I14 -> 2263 | M14: =N14/L14 -> 2.6547826 | N14: =E14+H14-K14 -> 6007.7729
A15: 卡板托盘 | B15: 套
A16: 胶带 | B16: 平方米
A17: 合 计 | C17: =SUM(C5:C16) -> 69746.173 | E17: =SUM(E5:E16) -> 514366.56 | F17: =SUM(F5:F16) -> 10619.41 | H17: =SUM(H5:H16) -> 540390.27 | I17: =SUM(I5:I16) -> 30671.871 | K17: =SUM(K5:K16) -> 778924.04 | L17: =SUM(L5:L16) -> 49693.712 | N17: =SUM(N5:N16) -> 275832.79 | O17: =S5 -> 0
J18: =SUM(K10:K16)/(SUM(I10:I16)+(I11+I7)/1000) -> 1.5274079
F19: =159.744+68.936+4501.471+45636+390 -> 50756.151 | H19: 913805.31
F20: =F19-F17 -> 40136.741 | H20: =H19-H17 -> 373415.04
I21: =SUM(I5:I15) -> 30671.871 | J21: =K21/I21 -> 25.395387 | K21: =SUM(K5:K15) -> 778924.04 | N21: =测算表!G13/0.13-N17 -> 416207.91
I26: 钢珠 | J26: 0.005 | K26: =J26*产品成本!$B$16/J11 -> 1122.4669
I27: 滑轨塑料配件 | J27: 0.008 | K27: =J27*产品成本!$B$16/J12 -> 21327.522
I28: 润滑脂 | J28: 0.007 | K28: =J28*产品成本!$B$16/J13 -> 42.624365
I29: 纸箱 | J29: 0.017 | K29: =J29*产品成本!$B$16/J14 -> 8309.176
I30: 卡板托盘 | J30: 0.02 | K30: =J30*产品成本!$B$16/J15 -> #DIV/0!

Sheet 测算表
A1: 销售废料0元 | E1: =B2+D4 -> 1206293.9 | H1: 含税 | I1: 金额 | J1: 税额
A2: 收入 | B2: =销售成本!E12+H7 -> 1067516.7 | G2: 冲减无票销售 | J2: =H2-I2 -> 0 | K2: =H2/1.13 -> 0
A3: 成本 | B3: =销售成本!J12+K7 -> 1002514.3 | C3: 增值税 | D3: =(D4-F4-F5) -> 26247.34
C4: 销项 | D4: 138777.17 | E4: 进项 | F4: =F13 -> 112529.83 | H4: =生产成本月结表!J4 -> -2014.4757
A5: 生产成本 | B5: =B6+B7+B8 -> 1276279.3 | E5: 留抵
A6: 1.材料 | B6: =产品成本!B5 -> 938011.81 | H6: 金额 | I6: 税额 | J6: 含税
A7: 1.工资 | B7: 121740 | E7: =生产成本月结表!J5 -> -19.184063 | G7: 废铁 | J7: =H7+I7 -> 0 | K7: =废料!X119*0 -> 0
A8: 3.制造费用 | B8: =B9+B10+B11 -> 216527.5 | G8: 开票销售 | J8: =H8+I8 -> 0
A9: 3.1折旧 | B9: 3567.6 | D9: 期初电 | E9: 期末电 | G9: 无票销售 | H9: =H10-H7-H8 -> 0 | I9: =I10-I7-I8 -> 0 | J9: =J10-J7-J8 -> 0
A10: 3.2电费 | B10: =电费!E63 -> 9054.9 | D10: =生产成本月结表!B6 -> 6028.24 | E10: =生产成本月结表!E6 -> 2376.2958
A11: 3.3加工费 | B11: =产品成本!B11-生产成本月结表!B8 -> 203905
D12: 期初待抵 | E12: 本期增加 | F12: 本期认证 | G12: 期末留抵
A13: 主营业务税金及附加 | B13: =B14+B15+B16+B17 -> 1574.8304 | D13: 122784.06 | E13: =E14+1177.14+8283.19 -> 79711.06 | F13: 112529.83 | G13: =D13+E13-F13 -> 89965.29
A14: 1.城建税 | B14: =D3*0.07/2-0.01 -> 918.6469 | E14: 70250.73
A15: 2.教育费附加 | B15: =IF(B2<100000,0,D3*0.03/2) -> 393.7101 | G15: 89965.29 | H15: =G13-G15 -> 0
A16: 3.地方教育费附加 | B16: =IF(B2<100000,0,D3*0.02/2) -> 262.4734
D17: 年销售额 | E17: =E28/11*12 -> 8211367.6
A18: 销售费用 | B18: =B19+B20 -> 636 | D18: 年利润总额 | E18: 222369.28
A19: 出口服务费 | B19: 636 | D19: 投资者减除
A20: 运输费 | D20: 应纳税所得额 | E20: =E18-E19 -> 222369.28
D21: 应纳税额 | E21: =IF(E20<=30000,E20*0.05,IF(E20<=90000,E20*0.1-1500,IF(E20<=300000,E20*0.2-10500,IF(E20<=500000,E20*0.3-40500,E20*0.35-65500)))) -> 33973.856
A22: 营业利润 | B22: =B2-B3-B13-B18 -> 62791.539 | D22: 减免税额 | E22: =E21/2 -> 16986.928 | F22: =E22/E17 -> 0.0020687087 | G22: =E17*0.00206870879425307-E22 -> 0.0004421905
D23: 已缴纳税额 | E23: =1366.83+2284.43+5819.66 -> 9470.92
A24: 管理费用 | B24: =SUM(B25:B34) -> 26771.81 | D24: 缓交税额
A25: 1.工资 | B25: 5000 | D25: 应补税额 | E25: =E21-E22-E23-E24 -> 7516.008 | G25: 0.93645175
A26: 2.办公 | I26: 税款
A27: 3.差旅 | I27: =D3+B14+B15+B16+B34+E38 -> 44010.511
A28: 4.业务 | D28: 累计销售额 | E28: =生产成本月结表!B14 -> 7527087
A29: 5.保险 | D29: 利润总额 | E29: =E18/12*11 -> 203838.51
A30: 6.折旧 | D30: 实际利润总额 | E30: =177379.68+B46 -> 203838.51 | G30: =E28-E30 -> 7323248.5
A31: 7.福利费 | D31: 差异 | E31: =E30-E29 -> 0.0022748305
A32: 8.土地使用税 | B32: =1350+3600+2550 -> 7500 | D32: 投资者减除
A33: 9.房产税 | B33: =840+2142+554.4+210 -> 3746.4 | D33: 应纳税所得额 | E33: =E30-E32 -> 203838.51
A34: 10.社保费 | B34: =475.44*4+8623.65 -> 10525.41 | D34: 应纳税额 | E34: =IF(E33<=30000,E33*0.05,IF(E33<=90000,E33*0.1-1500,IF(E33<=300000,E33*0.2-10500,IF(E33<=500000,E33*0.3-40500,E33*0.35-65500)))) -> 30267.702
D35: 减免税额 | E35: =E34/2 -> 15133.851
A36: 财务费用 | B36: =B38-B37+B39+B40-B41 -> 9560.9 | D36: 已缴纳税额 | E36: =E23 -> 9470.92
A37: 利息 | D37: 缓交税额 | E37: =E24 -> 0
A38: 手续费 | B38: =2.5+64.5+10 -> 77 | D38: 应补税额 | E38: =E34-E35-E36-E37 -> 5662.9309
A39: 贷款息 | B39: 3500 | E39: =E25-E38 -> 1853.0771
A40: 退税综合服务费 | B40: 5983.9
...

Sheet 工资
A1: 揭阳市揭东区磐东洪运来机械厂
A2: 2025年11月工资计算表
B3: 货币单位:元
A4: 部门名称 | B4: 应发金额
A5: 生产车间 | B5: =测算表!B7 -> 121740
A6: 管理部门 | B6: =测算表!B25 -> 5000
A7: 合 计 | B7: =B5+B6 -> 126740
B11: =B5/4500 -> 27.053333

Sheet 生产成本月结表
A1: 生产成本月结表
A2: 编制单位：揭阳市揭东区磐东洪运来机械厂 2025 年 11 月份 单位：元
A3: 项目 | B3: 上月结存 | C3: 本月发生 | D3: 本月结转 | E3: 本月结余 | F3: 备注
A4: 材料费 | B4: 336519.01 | C4: =材料!K17-材料!S11 -> 778924.04 | D4: =产品成本!B5+测算表!K7 -> 938011.81 | E4: =B4+C4-D4 -> 177431.24 | F4: =E4/E9 -> 0.86175243 | G4: =产品成本!B25 -> 0.72288683 | J4: =E6/(G6/G4)-E4 -> -2014.4757
A5: 工资 | B5: 43748.56 | C5: =测算表!B7 -> 121740 | D5: =产品成本!B7 -> 139400.26 | E5: =B5+C5-D5 -> 26088.304 | F5: =E5/E9 -> 0.12670632 | G5: =产品成本!B26 -> 0.10743 | J5: =E6/(G6/G5)-E5 -> -19.184063
A6: 动力 | B6: 6028.24 | C6: =测算表!B10 -> 9054.9 | D6: =产品成本!B9 -> 12706.844 | E6: =B6+C6-D6 -> 2376.2958 | F6: =E6/E9 -> 0.011541252 | G6: =产品成本!B27 -> 0.0097926382
A7: 折旧 | C7: =测算表!B9 -> 3567.6 | D7: =产品成本!B10 -> 3567.6
A8: 加工 | C8: =测算表!B11 -> 203905 | D8: =产品成本!B11 -> 203905
A9: 合 计 | B9: =SUM(B4:B8) -> 386295.81 | C9: =SUM(C4:C8) -> 1117191.5 | D9: =SUM(D4:D8) -> 1297591.5 | E9: =SUM(E4:E8) -> 205895.84
H11: =G12-H12 -> 6.0230612
G12: =E4+材料!N17 -> 453264.03 | H12: =F14*产品成本!B24 -> 453258.01
E13: =E9+材料!N17+销售成本!L12*0 -> 481728.63
A14: 累计销售额 | B14: =6459570.3+测算表!B2 -> 7527087 | D14: =材料!O17 -> 0 | E14: =E13/J14*0.13 -> 87042.853 | F14: =E14/0.13 -> 669560.41 | G14: =F14*C15 -> 15076.391 | J14: 0.71947
A15: 实缴 | B15: =143238.94+测算表!D3 -> 169486.28 | C15: =B15/B14 -> 0.022516849 | D15: =D14*0.13 -> 0 | E15: =测算表!G13 -> 89965.29
A16: 应缴 | B16: =B14*0.0222 -> 167101.33 | E16: =E14-E15 -> -2922.4366
A17: 多交 | B17: =B15-B16 -> 2384.9486
H18: =H11-F20 -> -120100.73
D19: =E16-D15 -> -2922.4366
E20: =G14-B17-D19 -> 15613.879 | F20: =E20/0.13 -> 120106.76 | G20: 少结材料 | H20: 开票单价提高
G21: 废料

Sheet 付工资
A1: 揭阳市揭东区磐东洪运来机械厂
A2: 工 资 表
E4: 单位：元 2025年10月
A6: 序号 | B6: 姓 名 | C6: 应发工资 | D6: 扣 款 | E6: 实发工资 | F6: 签 名 | J6: 姓名 | M6: 姓 名 | N6: 应发工资
B7: 李洪军 | C7: 2800 | D7: 0 | E7: =C7-D7 -> 2800 | I7: 1 | J7: 李洪军 | M7: 曾小琼 | N7: 3550
B8: 李静 | C8: 2200 | D8: 0 | E8: =C8-D8 -> 2200 | I8: 2 | J8: 李静 | M8: 陈云凤 | N8: 4840
B9: 杨泽明 | C9: 4840 | D9: 0 | E9: =C9-D9 -> 4840 | H9: =C9-1000 -> 3840 | I9: 3 | J9: 杨泽明 | M9: 代飞 | N9: 3270
B10: 余文平 | C10: 4080 | D10: 0 | E10: =C10-D10 -> 4080 | H10: =C10-1000 -> 3080 | I10: 4 | J10: 余文平 | M10: 代燕 | N10: 3470
B11: 陈云凤 | C11: 4840 | D11: 0 | E11: =C11-D11 -> 4840 | H11: =C11-1000 -> 3840 | I11: 5 | J11: 陈云凤 | M11: 代玉金 | N11: 4970
B12: 代玉金 | C12: 4970 | D12: 0 | E12: =C12-D12 -> 4970 | H12: =C12-1000 -> 3970 | I12: 6 | J12: 代玉金 | M12: 郭聪 | N12: 3750
B13: 杨艳群 | C13: 4860 | D13: 0 | E13: =C13-D13 -> 4860 | H13: =C13-1000 -> 3860 | I13: 7 | J13: 杨艳群 | M13: 李洪军 | N13: 2800
B14: 李金容 | C14: =3680+260 -> 3940 | D14: 0 | E14: =C14-D14 -> 3940 | H14: =C14-1000 -> 2940 | I14: 8 | J14: 李金容 | M14: 李金容 | N14: 3940
B15: 张贵华 | C15: 3680 | D15: 0 | E15: =C15-D15 -> 3680 | H15: =C15-1000 -> 2680 | I15: 9 | J15: 张贵华 | M15: 李静 | N15: 2200
B16: 王彬 | C16: 3320 | D16: 0 | E16: =C16-D16 -> 3320 | H16: =C16-1000 -> 2320 | I16: 10 | J16: 王彬 | M16: 刘华清 | N16: 3310
B17: 代燕 | C17: 3470 | D17: 0 | E17: =C17-D17 -> 3470 | H17: =C17-1000 -> 2470 | I17: 11 | J17: 代燕 | M17: 石光成 | N17: 3820
B18: 郭聪 | C18: 3750 | D18: 0 | E18: =C18-D18 -> 3750 | H18: =C18-1000 -> 2750 | I18: 12 | J18: 郭聪 | M18: 王彬 | N18: 3320
B19: 吴文荣 | C19: 3380 | D19: 0 | E19: =C19-D19 -> 3380 | H19: =C19-1000 -> 2380 | I19: 13 | J19: 吴文荣 | M19: 吴文荣 | N19: 3380
B20: 石光成 | C20: 3820 | D20: 0 | E20: =C20-D20 -> 3820 | H20: =C20-1000 -> 2820 | I20: 14 | J20: 石光成 | M20: 杨艳群 | N20: 4860
B21: 曾小琼 | C21: 3550 | D21: 0 | E21: =C21-D21 -> 3550 | H21: =C21-1000 -> 2550 | I21: 15 | J21: 曾小琼 | M21: 杨泽明 | N21: 4840
B22: 叶书香 | C22: =3470+90 -> 3560 | D22: 0 | E22: =C22-D22 -> 3560 | H22: =C22-1000 -> 2560 | I22: 16 | J22: 叶书香 | M22: 叶书香 | N22: 3560
B23: 代飞 | C23: 3270 | D23: 0 | E23: =C23-D23 -> 3270 | H23: =C23-1000 -> 2270 | I23: 17 | J23: 代飞 | M23: 余文平 | N23: 4080
B24: 刘华清 | C24: 3310 | D24: 0 | E24: =C24-D24 -> 3310 | H24: =C24-1000 -> 2310 | I24: 18 | J24: 刘华清 | M24: 张贵华 | N24: 3680
I25: 19 | J25: 谢苏玲
I26: 20 | J26: 钟玉婷
J27: 郑华强
J28: 郑文益
A29: 合 计 | C29: =SUM(C7:C28) -> 67640 | D29: =SUM(D7:D28) -> 0 | E29: =SUM(E7:E28) -> 67640 | J29: 杨玲
J30: 杨玉银
C31: =67640-C29 -> 0 | J31: 石珠福

Sheet 电费
B3: 2022年洪运来电费
B4: 月份 | C4: 度数（KWH） | D4: 单价 | E4: 金额（不含税 | F4: 税额 | G4: 金额（含税
B5: 1 | C5: 5962 | D5: =E5/C5 -> 0.78497149 | E5: 4680 | G5: =E5+F5 -> 4680
B6: 2 | C6: 8344 | D6: =E6/C6 -> 0.78499521 | E6: 6550 | G6: =E6+F6 -> 6550
B7: 3 | C7: 17771 | D7: =E7/C7 -> 0.78498678 | E7: 13950 | G7: =E7+F7 -> 13950
B8: 4 | C8: 6408 | D8: =E8/C8 -> 0.7849563 | E8: 5030 | G8: =E8+F8 -> 5030
B9: 5 | C9: 6268 | D9: =E9/C9 -> 0.78493937 | E9: 4920 | G9: =E9+F9 -> 4920
B10: 6 | C10: 19465 | D10: =E10/C10 -> 0.78499872 | E10: 15280 | G10: =E10+F10 -> 15280
B11: 7 | C11: 16917 | D11: =E11/C11 -> 0.78500916 | E11: 13280 | G11: =E11+F11 -> 13280
B12: 8 | C12: 22739 | D12: =E12/C12 -> 0.78499494 | E12: 17850 | G12: =E12+F12 -> 17850
B13: 9 | C13: 20280 | D13: =E13/C13 -> 0.78500986 | E13: 15920 | G13: =E13+F13 -> 15920
B14: 10 | C14: 12637 | D14: =E14/C14 -> 0.78499644 | E14: 9920 | G14: =E14+F14 -> 9920
A15: 付10月电费 | B15: 11 | C15: 22395 | D15: =E15/C15 -> 0.78499665 | E15: 17580 | G15: =E15+F15 -> 17580
A16: 付11月电费 | B16: 12 | C16: 22624 | D16: =E16/C16 -> 0.78500707 | E16: 17760 | G16: =E16+F16 -> 17760
C17: =SUM(C5:C16) -> 181810 | D17: =E17/C17 -> 0.78499532 | E17: =SUM(E5:E16) -> 142720 | F17: =SUM(F5:F16) -> 0 | G17: =SUM(G5:G16) -> 142720
B19: 2023年洪运来电费
B20: 月份 | C20: 度数（KWH） | D20: 单价 | E20: 金额（不含税 | F20: 税额 | G20: 金额（含税
A21: 付12月电费 | B21: 1 | C21: 13452 | D21: =E21/C21 -> 0.78501338 | E21: 10560 | G21: =E21+F21 -> 10560
A22: 付1月电费 | B22: 2 | C22: 12076 | D22: =E22/C22 -> 0.78502816 | E22: 9480 | G22: =E22+F22 -> 9480
A23: 付2月电费 | B23: 3 | C23: 7465 | D23: =E23/C23 -> 0.78499665 | E23: 5860 | G23: =E23+F23 -> 5860
A24: 付3月电费 | B24: 4 | C24: 27322 | D24: =E24/C24 -> 0.87548496 | E24: 23920 | G24: =E24+F24 -> 23920
A25: 付4月电费 | B25: 5 | C25: 9580 | D25: =E25/C25 -> 1.0200418 | E25: 9772 | G25: =E25+F25 -> 9772
A26: 付5月电费 | B26: 6 | C26: 17245 | D26: =E26/C26 -> 1.0200058 | E26: 17590 | G26: =E26+F26 -> 17590
A27: 付6月电费 | B27: 7 | C27: 8108 | D27: =E27/C27 -> 1.0199803 | E27: 8270 | G27: =E27+F27 -> 8270
A28: 付7月电费 | B28: 8 | C28: 5716 | D28: =E28/C28 -> 1.019944 | E28: 5830 | G28: =E28+F28 -> 5830
A29: 付8月电费 | B29: 9 | C29: 8657 | D29: =E29/C29 -> 1.0199838 | E29: 8830 | G29: =E29+F29 -> 8830
A30: 付9月电费 | B30: 10 | C30: 6152 | D30: =E30/C30 -> 1.0199935 | E30: 6275 | G30: =E30+F30 -> 6275
A31: 付10月电费 | B31: 11 | C31: 6647 | D31: =E31/C31 -> 1.020009 | E31: 6780 | G31: =E31+F31 -> 6780 | I31: 3693.6 | J31: =K31/I31 -> 0.72226825 | K31: 2667.77
A32: 付11月电费 | B32: 12 | C32: 6398 | D32: =E32/C32 -> 1.02 | E32: 6525.96 | G32: =E32+F32 -> 6525.96 | I32: 14638.8 | J32: =K32/I32 -> 0.72136855 | K32: 10559.97
C33: =SUM(C21:C32) -> 128818 | D33: =E33/C33 -> 0.92916332 | E33: =SUM(E21:E32) -> 119692.96 | F33: =SUM(F21:F32) -> 0 | G33: =SUM(G21:G32) -> 119692.96 | L33: 当月月头
L34: 揭阳市揭东区磐东洪运来机械厂
B35: 2024年洪运来电费 | L35: 上月电费 度*0.785元/度=
B36: 月份 | C36: 度数（KWH） | D36: 单价 | E36: 金额（不含税 | F36: 税额 | G36: 金额（含税 | M36: 李
A37: 付12月电费 | B37: 1 | C37: 19500 | D37: =E37/C37 -> 0.73316872 | E37: 14296.79 | G37: =E37+F37 -> 14296.79 | I37: =C37*50 -> 975000
A38: 付1月电费 | B38: 2 | C38: 13535.6 | D38: =E38/C38 -> 0.63244998 | E38: 8560.59 | F38: 1112.88 | G38: =E38+F38 -> 9673.47 | I38: =C38*50 -> 676780
A39: 付2月电费 | B39: 3 | C39: 2168 | D39: =E39/C39 -> 0.64890683 | E39: 1406.83 | F39: 182.89 | G39: =E39+F39 -> 1589.72 | I39: =C39*50 -> 108400
A40: 付3月电费 | B40: 4 | C40: 15748 | D40: =E40/C40 -> 0.63873317 | E40: 10058.77 | F40: 1307.64 | G40: =E40+F40 -> 11366.41 | I40: =C40*50 -> 787400
A41: 付4月电费 | B41: 5 | C41: 15079.6 | D41: =E41/C41 -> 0.63882132 | E41: 9633.17 | F41: 1252.31 | G41: =E41+F41 -> 10885.48 | I41: =C41*50 -> 753980
A42: 付5月电费 | B42: 6 | C42: 15882.8 | D42: =E42/C42 -> 0.63890939 | E42: 10147.67 | F42: 1319.2 | G42: =E42+F42 -> 11466.87 | I42: =C42*50 -> 794140
A43: 付6月电费 | B43: 7 | C43: 12502.8 | D43: =E43/C43 -> 0.61147663 | E43: 7645.17 | F43: 993.87 | G43: =E43+F43 -> 8639.04 | I43: =C43*50 -> 625140
...

Sheet 废料
B2: 品名 | C2: 单位 | D2: 上月结存 | G2: 本月进仓数 | J2: 本月发出数 | M2: 本月结余 | P2: 备注
D3: 数量 | E3: 单价 | F3: 金额 | G3: 数量 | H3: 单价 | I3: 金额 | J3: 数量 | K3: 单价 | L3: 金额 | M3: 数量 | N3: 单价 | O3: 金额
B4: 带钢 | C4: 吨 | D4: 89.063 | E4: 3913.4375 | F4: 348542.48 | G4: 178.262 | H4: 3720.7936 | I4: 663276.11 | J4: 180.64 | K4: 3784.9756 | L4: 683717.98 | M4: 86.685 | N4: 3784.9756 | O4: 328100.61 | P4: 5月
B5: 镀铝锌卷板 | C5: 吨 | G5: 7.745 | H5: 4010.581 | I5: 31061.95 | J5: 7.745 | K5: 4010.581 | L5: 31061.95 | M5: 0 | N5: #DIV/0! | O5: 0 | P5: 5月
J12: =SUM(J4:J7) -> 188.385 | K12: =L12/J12 -> 3794.2508 | L12: =SUM(L4:L7) -> 714779.93 | O12: =测算表!H20/0.13-O8 -> 0
J13: =J12*0.09 -> 16.95465 | K13: 2930 | L13: =J13*K13 -> 49677.124
I17: 废料销售 | J17: 7 | K17: 2700 | L17: 18900 | M17: 4月未销售废料
I18: 废料销售 | J18: 18.5 | K18: 2886.0503 | L18: 53391.93 | M18: 5月未销售废料
I19: 废料销售 | J19: 3.375 | K19: 2834.9778 | L19: 9568.0502 | M19: 6月未销售废料
I20: 废料销售 | J20: 1.7919 | K20: 2834.9778 | L20: 5079.9968 | M20: 7月未销售废料
I21: 废料销售 | J21: 6.42321 | K21: 2834.9778 | L21: 18209.66 | M21: 8月未销售废料
I22: 废料销售 | J22: 10.06848 | K22: =L22/J22 -> 2834.9781 | L22: 28543.92 | M22: 9月未销售废料
I23: 废料销售 | J23: 10.22121 | K23: 2834.9778 | L23: 28976.9 | M23: 10月未销售废料
I24: 废料销售 | J24: 16.785 | K24: =L24/J24 -> 2834.9783 | L24: 47585.11 | M24: 11月未销售废料
I25: 废料销售 | J25: 19.075 | K25: =L25/J25 -> 3299.4522 | L25: 62937.05 | M25: 12月未销售废料
J27: =SUM(J17:J26) -> 93.2398 | K27: =2930 -> 2930 | L27: =SUM(L17:L26) -> 273192.62 | N27: =L27/1.13 -> 241763.38 | O27: =生产成本月结表!F11 -> 0
L28: =J27*K27-L17-L18-L19-L20-L21-L22-L23-L24 -> 62937.047 | O28: =N27-O27 -> 241763.38
J30: 85.324 | K30: =L30/J30 -> 2930.008 | L30: 250000 | N30: =L30/1.13 -> 221238.94
I31: 废料销售 | J31: =J27-J30 -> 7.9158 | K31: =L31/J31 -> 2929.9145 | L31: =L27-L30 -> 23192.617 | M31: 12月未销售废料 | N31: =L31/1.13 -> 20524.44 | O31: =N31*0.964963653865046 -> 19805.338
I32: 废料销售 | J32: 16.84593 | K32: =L32/J32 -> 2930 | L32: 49358.575 | M32: 1月未销售废料 | N32: =L32/1.13 -> 43680.155 | O32: =N32*0.964963653865046 -> 42149.762
I33: 废料销售 | J33: 10.01151 | K33: =L33/J33 -> 2930.0679 | L33: =29333.7243+0.68 -> 29334.404 | M33: 2月未销售废料 | N33: =L33/1.13 -> 25959.65 | O33: =N33*0.964963653865046 -> 25050.119
I34: 废料销售 | J34: 9.83223 | K34: 2930 | L34: 28808.434 | M34: 3月未销售废料 | N34: =L34/1.13 -> 25494.189 | O34: =N34*0.964963653865046 -> 24600.966
I35: 废料销售 | J35: 6.52545 | K35: 2930 | L35: 19119.569 | M35: 4月未销售废料 | N35: =L35/1.13 -> 16919.972 | O35: =N35*0.964963653865046 -> 16327.158
I36: 废料销售 | J36: 16.95465 | K36: 2930 | L36: 49677.124 | M36: 5月未销售废料 | N36: =L36/1.13 -> 43962.057 | O36: =N36*0.964963653865046 -> 42421.787
J39: =SUM(J31:J38) -> 68.08557 | K39: 2930 | L39: =SUM(L31:L38) -> 199490.72 | N39: =SUM(N31:N38) -> 176540.46 | O39: =SUM(O31:O38) -> 170355.13
L40: =J39*K39-L31-L32-L33-L34-L35 -> 49677.121 | O40: =N39-O39 -> 6185.3328
I42: 预测废料 | J42: =J27-J30+J39 -> 76.00137 | K42: =L42/J42 -> 2929.9911 | L42: =L27-L30+L39 -> 222683.34
R45: 以上废料已结算
U47: 数量 | V47: 单价 | W47: 金额 | X47: 税额 | Y47: 含税金额
B48: 品名 | C48: 单位 | D48: 上月结存 | G48: 本月进仓数 | J48: 本月发出数 | M48: 本月结余 | P48: 备注 | R48: 45467 | S48: *金属制品*废铁 | T48: 吨 | U48: 68.259 | V48: =W48/U48 -> 2592.935 | W48: 176991.15 | X48: 23008.85 | Y48: 200000
D49: 数量 | E49: 单价 | F49: 金额 | G49: 数量 | H49: 单价 | I49: 金额 | J49: 数量 | K49: 单价 | L49: 金额 | M49: 数量 | N49: 单价 | O49: 金额 | V49: =Y48/U48 -> 2930.0166
B50: 带钢 | C50: 吨 | D50: 86.685 | E50: 3784.9756 | F50: 328100.61 | G50: 75.48 | H50: 3820.2349 | I50: 288351.33 | J50: 102.786 | K50: 3801.3871 | L50: 390729.38 | M50: 59.379 | N50: 3801.3871 | O50: 225722.56 | P50: 6月
B51: 镀锌带钢 | C51: 吨 | G51: 8.234 | H51: 4309.7802 | I51: 35486.73 | J51: 8.234 | K51: 4309.7802 | L51: 35486.73 | M51: 0 | N51: #DIV/0! | O51: 0 | P51: 6月
B52: 带钢 | C52: 吨 | D52: 59.379 | E52: 3801.387 | F52: 225722.56 | G52: 259.376 | H52: 3828.8215 | I52: 993104.41 | J52: 79 | K52: 3823.7109 | L52: 302073.16 | M52: 239.755 | N52: 3823.7109 | O52: 916753.81 | P52: 7月
B53: 带钢 | C53: 吨 | D53: 239.755 | E53: 3823.7109 | F53: 916753.81 | G53: 104.677 | H53: 3678.9109 | I53: 385097.36 | J53: 106.6 | K53: 3779.7045 | L53: 402916.5 | M53: 237.832 | N53: 3779.7045 | O53: 898934.67 | P53: 8月
B54: 镀锌带钢 | C54: 吨 | D54: 9.086 | E54: 4310.044 | F54: 39161.06 | J54: 9.086 | K54: 4310.044 | L54: 39161.06 | M54: 0 | N54: #DIV/0! | O54: 0 | P54: 8月
B55: 冷轧板卷 | C55: 吨 | D55: 10.448 | E55: 3913.0159 | F55: 40883.19 | J55: 10.448 | K55: 3913.0159 | L55: 40883.19 | M55: 0 | N55: #DIV/0! | O55: 0 | P55: 8月 | R55: 2024.10.26 | S55: *金属制品*废铁 | T55: 吨 | U55: 11.54 | V55: =W55/U55 -> 2300.578 | W55: 26548.67 | X55: 3451.33 | Y55: 30000
B56: 带钢 | C56: 吨 | D56: 237.832 | E56: 3779.7045 | F56: 898934.67 | G56: 56.07 | H56: 3650.7621 | I56: 204698.23 | J56: 154.8 | K56: 3755.1051 | L56: 581290.27 | M56: 139.102 | N56: 3755.1051 | O56: 522342.63 | P56: 9月 | V56: =Y55/U55 -> 2599.6534 | W56: =W55/N65*O65 -> 25618.502
G63: =K64*1.13 -> 4300.9944
G64: =K65/G63 -> 0.68123781 | J64: =SUM(J50:J59) -> 470.954 | K64: =L64/J64 -> 3806.1897 | L64: =SUM(L50:L59) -> 1792540.3
...

Sheet 加工成本
A1: 揭阳市揭东区磐东洪运来机械厂
A2: 加工成本计算表
A3: 项 目 | B3: 数量 | C3: 单位 | D3: 单位成本 | E3: 合 计
A4: 工 资 | C4: 吨 | D4: 323
A5: 制造费用 | C5: 吨 | D5: 645 | E5: =E12*0.45149*0.954 -> 0
A6: 总 计 | B6: =B4 -> 0 | D6: 968 | E6: =E4+E5 -> 0
A12: 加工收入： | E12: =E11/1.17 -> 0
A14: 加工利润 | E14: =E12-E6 -> 0
A16: 毛利率 | E16: =E14/E12 -> #DIV/0!
